<?xml version="1.0"?>
<robot xmlns:xacro="http://www.ros.org/wiki/xacro" name="manipulator">
    <xacro:include filename="$(find rrr_description)/urdf/robot_gazebo.xacro"/> 
    <xacro:include filename="$(find rrr_description)/urdf/robot_ros2_control.xacro"/> 

    <xacro:macro name="default_inertial" params="mass">
        <inertial>
                <mass value="1" />
                <inertia ixx="1.0" ixy="0.0" ixz="0.0"
                     iyy="1.0" iyz="0.0"
                     izz="1.0" />
        </inertial>
    </xacro:macro>
    <material name="white">
        <color rgba="1 1 1 1"/>
    </material>
    <material name="green">
        <color rgba="0 0.6 0 1"/>
    </material>
    <link name="base_link">
        <visual>
            <geometry>
                <cylinder length="0.02" radius="0.15" />
            </geometry>
            <material name="green"/>
            <origin xyz="0 0 0.01" rpy="0 0 0"/>
        </visual>
        <collision>
            <geometry>
                <cylinder length="0.02" radius="0.15" />
            </geometry>
            <origin xyz="0 0 0.01" rpy="0 0 0"/>
        </collision>
        <xacro:default_inertial mass="1"/>
    </link>
    <gazebo reference="base_link">
        <material>Gazebo/Green</material>
    </gazebo>
    <link name="link1">
        <visual>
            <geometry>
                <cylinder length="0.1" radius="0.1" />
            </geometry>
            <material name="green"/>
            <origin xyz="0 0 0.05" rpy="0 0 0"/>
        </visual>
        <collision>
            <geometry>
                <cylinder length="0.1" radius="0.1" />
            </geometry>
            <origin xyz="0 0 0.05" rpy="0 0 0"/>
        </collision>
        <xacro:default_inertial mass="1"/>
    </link>
    <gazebo reference="link1">
        <material>Gazebo/Green</material>
    </gazebo>
    <joint name="joint1" type="revolute">
        <origin rpy="0 0 0" xyz="0 0 0.018" />
        <parent link="base_link" />
        <child link="link1" />
        <axis xyz="0 0 1" />
        <limit lower="-1.57" upper="1.57" effort="100" velocity="1" />
    </joint>
    <link name="link2">
        <visual>
            <geometry>
                <cylinder length="0.30" radius="0.03" />
            </geometry>
            <material name="white"/>
            <origin xyz="0 0 0.15" rpy="0 0 0"/>
        </visual>
        <collision>
            <geometry>
                <cylinder length="0.30" radius="0.03" />
            </geometry>
            <origin xyz="0 0 0.15" rpy="0 0 0"/>
        </collision>
        <xacro:default_inertial mass="1"/>
    </link>
    <gazebo reference="link2">
        <material>Gazebo/White</material>
    </gazebo>
    <joint name="joint2" type="revolute">
        <origin rpy="0 0 0" xyz="0 0 0.08" />
        <parent link="link1" />
        <child link="link2" />
        <axis xyz="0 1 0" />
        <limit lower="-1.57" upper="1.57" effort="100" velocity="1" />
    </joint>
    <link name="link3">
        <visual>
            <geometry>
                <cylinder length="0.30" radius="0.03" />
            </geometry>
            <material name="white"/>
            <origin xyz="0 0 0.15" rpy="0 0 0"/>
        </visual>
        <collision>
            <geometry>
                <cylinder length="0.30" radius="0.03" />
            </geometry>
            <origin xyz="0 0 0.15" rpy="0 0 0"/>
        </collision>
        <xacro:default_inertial mass="1"/>
    </link>
    <gazebo reference="link3">
        <material>Gazebo/White</material>
    </gazebo>
    <joint name="joint3" type="revolute">
        <origin rpy="0 0 0" xyz="0 0 0.28" />
        <parent link="link2" />
        <child link="link3" />
        <axis xyz="0 1 0" />
        <limit lower="-1.57" upper="1.57" effort="100" velocity="1" />
    </joint>
    <link name="wrist">
        <visual>
            <geometry>
                <box size="0.12 0.08 0.07" />
            </geometry>
            <material name="green"/>
            <origin xyz="0 0 0.035" rpy="0 0 0"/>
        </visual>
        <collision>
            <geometry>
                <box size="0.12 0.08 0.07" />
            </geometry>
            <origin xyz="0 0 0.035" rpy="0 0 0"/>
        </collision>
        <xacro:default_inertial mass="1"/>
    </link>
    <gazebo reference="wrist">
        <material>Gazebo/Green</material>
    </gazebo>
    <joint name="joint4" type="fixed">
        <origin rpy="0 0 0" xyz="0 0 0.3" />
        <parent link="link3" />
        <child link="wrist" />
        <axis xyz="0 1 0" />
    </joint>
    <link name="finger_1">
        <visual>
            <geometry>
                <box size="0.02 0.02 0.07" />
            </geometry>
            <material name="green"/>
            <origin xyz="0 0 0.025" rpy="0 0 0"/>
        </visual>
        <collision>
            <geometry>
                <box size="0.02 0.02 0.07" />
            </geometry>
            <origin xyz="0 0 0.025" rpy="0 0 0"/>
        </collision>
        <xacro:default_inertial mass="1"/>
    </link>
    <gazebo reference="finger_1">
        <material>Gazebo/Green</material>
    </gazebo>
    <joint name="finger_joint1" type="prismatic">
        <origin rpy="0 0 0" xyz="-0.04 0 0.07" />
        <parent link="wrist" />
        <child link="finger_1" />
        <axis xyz="1 0 0" />
        <limit lower="0" upper="0.03" effort="100" velocity="1" />
    </joint>    
    <link name="finger_2">
        <visual>
            <geometry>
                <box size="0.02 0.02 0.07" />
            </geometry>
            <material name="green"/>
            <origin xyz="0 0 0.025" rpy="0 0 0"/>
        </visual>
        <collision>
            <geometry>
                <box size="0.02 0.02 0.07" />
            </geometry>
            <origin xyz="0 0 0.025" rpy="0 0 0"/>
        </collision>
        <xacro:default_inertial mass="1"/>
    </link>
    <gazebo reference="finger_2">
        <material>Gazebo/Green</material>
    </gazebo>
    <joint name="finger_joint2" type="prismatic">
        <origin rpy="0 0 0" xyz="0.04 0 0.07" />
        <parent link="wrist" />
        <child link="finger_2" />
        <axis xyz="1 0 0" />
        <limit lower="-0.03" upper="0" effort="100" velocity="1" />
    </joint>        
</robot>